Workbook
Name SegmentaçãodeDados_Anos: #N/A

Sheet Dados
A1: VENCTO. | B1: EST | C1: DUPLIC. | D1: CNPJ/CPF | E1: CLIENTE | F1: EMISSÃO | G1: PRAZO | H1: VALOR | I1: N.F | J1: AG. COB. | K1: SIT. | L1: Vendedor | M1: Cidade
A2: 40983 | B2: 0 | C2: 851026 | D2: 02768292000132 | E2: FRANCISCA LOPES CARNEIRO ME | F2: 40910 | G2: 73 | H2: 2777.77 | J2: 900 | K2: A | L2: JOÃO BATISTA FERNANDES PIMENTEL | M2: ITAPAJE
A3: 40988 | B3: 0 | C3: 850954 | D3: 02768292000132 | E3: FRANCISCA LOPES CARNEIRO ME | F3: 40744 | G3: 244 | H3: 1750 | J3: 900 | K3: A | L3: JOÃO BATISTA FERNANDES PIMENTEL | M3: ITAPAJE
A4: 41004 | B4: 0 | C4: 850933 | D4: 02768292000132 | E4: FRANCISCA LOPES CARNEIRO ME | F4: 40744 | G4: 260 | H4: 6075 | J4: 900 | K4: A | L4: JOÃO BATISTA FERNANDES PIMENTEL | M4: ITAPAJE
A5: 41008 | B5: 0 | C5: 850900 | D5: 02768292000132 | E5: FRANCISCA LOPES CARNEIRO ME | F5: 40647 | G5: 361 | H5: 1926.93 | J5: 900 | K5: A | L5: JOÃO BATISTA FERNANDES PIMENTEL | M5: ITAPAJE
A6: 41015 | B6: 0 | C6: 851015 | D6: 02768292000132 | E6: FRANCISCA LOPES CARNEIRO ME | F6: 40910 | G6: 105 | H6: 2777.77 | J6: 900 | K6: A | L6: JOÃO BATISTA FERNANDES PIMENTEL | M6: ITAPAJE
A7: 41019 | B7: 0 | C7: 850931 | D7: 02768292000132 | E7: FRANCISCA LOPES CARNEIRO ME | F7: 40744 | G7: 275 | H7: 6075 | J7: 900 | K7: A | L7: JOÃO BATISTA FERNANDES PIMENTEL | M7: ITAPAJE
A8: 41036 | B8: 0 | C8: 850927 | D8: 02768292000132 | E8: FRANCISCA LOPES CARNEIRO ME | F8: 40744 | G8: 292 | H8: 6075 | J8: 900 | K8: A | L8: JOÃO BATISTA FERNANDES PIMENTEL | M8: ITAPAJE
A9: 41036 | B9: 0 | C9: 850901 | D9: 02768292000132 | E9: FRANCISCA LOPES CARNEIRO ME | F9: 40647 | G9: 389 | H9: 1926.93 | J9: 900 | K9: A | L9: JOÃO BATISTA FERNANDES PIMENTEL | M9: ITAPAJE
A10: 41044 | B10: 0 | C10: 851016 | D10: 02768292000132 | E10: FRANCISCA LOPES CARNEIRO ME | F10: 40910 | G10: 134 | H10: 2777.77 | J10: 900 | K10: A | L10: JOÃO BATISTA FERNANDES PIMENTEL | M10: ITAPAJE
A11: 41050 | B11: 0 | C11: 850928 | D11: 02768292000132 | E11: FRANCISCA LOPES CARNEIRO ME | F11: 40744 | G11: 306 | H11: 6075 | J11: 900 | K11: A | L11: JOÃO BATISTA FERNANDES PIMENTEL | M11: ITAPAJE
A12: 41067 | B12: 0 | C12: 850902 | D12: 02768292000132 | E12: FRANCISCA LOPES CARNEIRO ME | F12: 40647 | G12: 420 | H12: 1926.93 | J12: 900 | K12: A | L12: JOÃO BATISTA FERNANDES PIMENTEL | M12: ITAPAJE
A13: 41075 | B13: 0 | C13: 851017 | D13: 02768292000132 | E13: FRANCISCA LOPES CARNEIRO ME | F13: 40910 | G13: 165 | H13: 2777.77 | J13: 900 | K13: A | L13: JOÃO BATISTA FERNANDES PIMENTEL | M13: ITAPAJE
... A18: 41159 | B18: 0 | C18: 850905 | D18: 02768292000132 | E18: FRANCISCA LOPES CARNEIRO ME | F18: 40647 | G18: 512 | H18: 1926.93 | J18: 900 | K18: A | L18: JOÃO BATISTA FERNANDES PIMENTEL | M18: ITAPAJE
A19: 41165 | B19: 0 | C19: 56832D | D19: 73412058000116 | E19: VIRGINIA SABINO MACHADO | F19: 41019 | G19: 146 | H19: 3596.21 | I19: 1/56832 | J19: 1 | K19: A | M19: OCARA
A20: 41169 | B20: 0 | C20: 851020 | D20: 02768292000132 | E20: FRANCISCA LOPES CARNEIRO ME | F20: 40910 | G20: 259 | H20: 2777.77 | J20: 900 | K20: A | L20: JOÃO BATISTA FERNANDES PIMENTEL | M20: ITAPAJE
A21: 41190 | B21: 0 | C21: 850906 | D21: 02768292000132 | E21: FRANCISCA LOPES CARNEIRO ME | F21: 40647 | G21: 543 | H21: 1926.93 | J21: 900 | K21: A | L21: JOÃO BATISTA FERNANDES PIMENTEL | M21: ITAPAJE
A22: 41197 | B22: 0 | C22: 851021 | D22: 02768292000132 | E22: FRANCISCA LOPES CARNEIRO ME | F22: 40910 | G22: 287 | H22: 2777.77 | J22: 900 | K22: A | L22: JOÃO BATISTA FERNANDES PIMENTEL | M22: ITAPAJE
A23: 41228 | B23: 0 | C23: 851022 | D23: 02768292000132 | E23: FRANCISCA LOPES CARNEIRO ME | F23: 40910 | G23: 318 | H23: 2777.77 | J23: 900 | K23: A | L23: JOÃO BATISTA FERNANDES PIMENTEL | M23: ITAPAJE
A24: 41247 | B24: 0 | C24: 062009E | D24: 23598576000106 | E24: LIMA & SABINO SOCIEDADE FARMACEUTICA LTDA | F24: 41152 | G24: 95 | H24: 628.15 | I24: 1/62009 | J24: 1 | K24: A | M24: CHOROZINHO
A25: 41250 | B25: 0 | C25: 062387C | D25: 73412058000116 | E25: VIRGINIA SABINO MACHADO | F25: 41163 | G25: 87 | H25: 1138.74 | I25: 1/62387 | J25: 1 | K25: A | L25: JARDEL MONTEIRO | M25: OCARA
A26: 41260 | B26: 0 | C26: 851023 | D26: 02768292000132 | E26: FRANCISCA LOPES CARNEIRO ME | F26: 40910 | G26: 350 | H26: 2777.77 | J26: 900 | K26: A | L26: JOÃO BATISTA FERNANDES PIMENTEL | M26: ITAPAJE
A27: 41289 | B27: 0 | C27: 851024 | D27: 02768292000132 | E27: FRANCISCA LOPES CARNEIRO ME | F27: 40910 | G27: 379 | H27: 2777.77 | J27: 900 | K27: A | L27: JOÃO BATISTA FERNANDES PIMENTEL | M27: ITAPAJE
A28: 41320 | B28: 0 | C28: 851025 | D28: 02768292000132 | E28: FRANCISCA LOPES CARNEIRO ME | F28: 40910 | G28: 410 | H28: 2777.77 | J28: 900 | K28: A | L28: JOÃO BATISTA FERNANDES PIMENTEL | M28: ITAPAJE
A29: 41348 | B29: 0 | C29: 851046 | D29: 02768292000132 | E29: FRANCISCA LOPES CARNEIRO ME | F29: 40910 | G29: 438 | H29: 8061.74 | J29: 900 | K29: A | L29: JOÃO BATISTA FERNANDES PIMENTEL | M29: ITAPAJE
A30: 41409 | B30: 0 | C30: 851044 | D30: 02768292000132 | E30: FRANCISCA LOPES CARNEIRO ME | F30: 40910 | G30: 499 | H30: 8061.74 | J30: 900 | K30: A | L30: JOÃO BATISTA FERNANDES PIMENTEL | M30: ITAPAJE
A31: 41470 | B31: 0 | C31: 851042 | D31: 02768292000132 | E31: FRANCISCA LOPES CARNEIRO ME | F31: 40910 | G31: 560 | H31: 8061.74 | J31: 900 | K31: A | L31: JOÃO BATISTA FERNANDES PIMENTEL | M31: ITAPAJE
A32: 41533 | B32: 0 | C32: 851040 | D32: 02768292000132 | E32: FRANCISCA LOPES CARNEIRO ME | F32: 40910 | G32: 623 | H32: 8061.74 | J32: 900 | K32: A | L32: JOÃO BATISTA FERNANDES PIMENTEL | M32: ITAPAJE
A33: 41562 | B33: 0 | C33: 851039 | D33: 02768292000132 | E33: FRANCISCA LOPES CARNEIRO ME | F33: 40910 | G33: 652 | H33: 8061.74 | J33: 900 | K33: A | L33: JOÃO BATISTA FERNANDES PIMENTEL | M33: ITAPAJE
A34: 41593 | B34: 0 | C34: 851038 | D34: 02768292000132 | E34: FRANCISCA LOPES CARNEIRO ME | F34: 40910 | G34: 683 | H34: 8061.74 | J34: 900 | K34: A | L34: JOÃO BATISTA FERNANDES PIMENTEL | M34: ITAPAJE
A35: 41624 | B35: 0 | C35: 851037 | D35: 02768292000132 | E35: FRANCISCA LOPES CARNEIRO ME | F35: 40910 | G35: 714 | H35: 8061.74 | J35: 900 | K35: A | L35: JOÃO BATISTA FERNANDES PIMENTEL | M35: ITAPAJE
A36: 41654 | B36: 0 | C36: 851030 | D36: 02768292000132 | E36: FRANCISCA LOPES CARNEIRO ME | F36: 41654 | G36: 0 | H36: 8061.74 | J36: 900 | K36: A | L36: JOÃO BATISTA FERNANDES PIMENTEL | M36: ITAPAJE
A37: 41687 | B37: 0 | C37: 851029 | D37: 02768292000132 | E37: FRANCISCA LOPES CARNEIRO ME | F37: 41685 | G37: 2 | H37: 8061.74 | J37: 900 | K37: A | L37: JOÃO BATISTA FERNANDES PIMENTEL | M37: ITAPAJE
A38: 41715 | B38: 0 | C38: 851028 | D38: 02768292000132 | E38: FRANCISCA LOPES CARNEIRO ME | F38: 41713 | G38: 2 | H38: 8061.74 | J38: 900 | K38: A | L38: JOÃO BATISTA FERNANDES PIMENTEL | M38: ITAPAJE
A39: 41932 | B39: 0 | C39: 095721A | D39: 73412058000116 | E39: VIRGINIA SABINO MACHADO | F39: 41870 | G39: 62 | H39: 351.16 | I39: 1/95721 | J39: 1 | K39: A | M39: OCARA
A40: 42121 | B40: 0 | C40: 106295A | D40: 73412058000116 | E40: VIRGINIA SABINO MACHADO | F40: 42055 | G40: 66 | H40: 361.38 | I40: 1/106295 | J40: 1 | K40: A | M40: OCARA
A41: 42219 | B41: 0 | C41: 000034 | D41: 20273313000120 | E41: F.E COMERCIAL FARMACEUTICO - ME | F41: 42219 | G41: 0 | H41: 2138 | J41: 900 | K41: A | L41: EDILBERTO XAVIER DOS SANTOS | M41: EUSEBIO
A42: 42226 | B42: 0 | C42: 117310A | D42: 20273313000120 | E42: F.E COMERCIAL FARMACEUTICO - ME | F42: 42220 | G42: 6 | H42: 531.93 | I42: 1/117310 | J42: 1 | K42: A | L42: EDILBERTO XAVIER DOS SANTOS | M42: EUSEBIO
A43: 42227 | B43: 0 | C43: 117313A | D43: 20273313000120 | E43: F.E COMERCIAL FARMACEUTICO - ME | F43: 42220 | G43: 7 | H43: 552.51 | I43: 1/117313 | J43: 1 | K43: A | L43: EDILBERTO XAVIER DOS SANTOS | M43: EUSEBIO
A44: 42228 | B44: 0 | C44: 117406A | D44: 20273313000120 | E44: F.E COMERCIAL FARMACEUTICO - ME | F44: 42221 | G44: 7 | H44: 375.39 | I44: 1/117406 | J44: 1 | K44: A | L44: EDILBERTO XAVIER DOS SANTOS | M44: EUSEBIO
...

Sheet Indicador
N5: BRINDE | P5: BRINDE
B6: Vencido | E6: =IFERROR(E35/E8,0) -> 0 | F6: =IFERROR(F35/F8,0) -> 0 | G6: =IFERROR(G35/G8,0) -> 0.00017247749 | H6: =IFERROR(H35/H8,0) -> 0.00031476641 | I6: =IFERROR(I35/I8,0) -> 0.0005593538 | J6: =IFERROR(J35/J8,0) -> 0.00026081065 | K6: =IFERROR(K35/K8,0) -> 0.00014917426 | L6: =IFERROR(L35/L8,0) -> 0 | M6: =L35/M8 -> 0
B7: Período | C7: VENDA 2012 | D7: VENDA 2013 | E7: VENDA 2014 | F7: VENDA 2015 | G7: VENDA 2016 | H7: VENDA 2017 | I7: VENDA 2018 | J7: VENDA 2019 | K7: VENDA 2020 | L7: VENDA 2021 | M7: Total | N7: VENDA 2020 | O7: % 2020 | P7: VENDA 2021 | Q7: % 2021
B8: Mês | C8: =SUM(C9:C20) -> 0 | D8: =SUM(D9:D20) -> 0 | E8: =SUM(E9:E20) -> 15936547 | F8: =SUM(F9:F20) -> 19335117 | G8: =SUM(G9:G20) -> 19661696 | H8: =SUM(H9:H20) -> 20416822 | I8: =SUM(I9:I20) -> 21381512 | J8: =SUM(J9:J20) -> 27927924 | ... M8: =SUM(M9:M20) -> 1.6424219e+08
B9: jan | C9: 0 | D9: 0 | E9: 1250752.5 | F9: 1453249.7 | G9: 1433953.3 | H9: 1801431.2 | I9: 1534692.2 | J9: 1803035.8 | K9: 2723764.3 | L9: 3613932.5 | M9: =SUM(E9:K9) -> 12000879 | N9: 0 | O9: =IFERROR(N9/K9,0) -> 0 | P9: 280647.86 | Q9: =IFERROR(P9/L9,0) -> 0.077657194
B10: fev | C10: 0 | D10: 0 | E10: 1115431.2 | F10: 1291304.6 | G10: 1669255.6 | H10: 1715515 | I10: 1531791.9 | J10: 2020158.9 | K10: 2554882.4 | L10: 3002902.1 | M10: =SUM(E10:K10) -> 11898340 | N10: 0 | O10: =IFERROR(N10/K10,0) -> 0 | P10: 0 | Q10: =IFERROR(P10/L10,0) -> 0
B11: mar | C11: 0 | D11: 0 | E11: 1087833.7 | F11: 1862650.1 | G11: 1971098.7 | H11: 2433346.4 | I11: 1749327.5 | J11: 2185357.9 | K11: 3998716.1 | L11: 4889993.3 | M11: =SUM(E11:K11) -> 15288331 | N11: 0 | O11: =IFERROR(N11/K11,0) -> 0 | P11: 0 | Q11: =IFERROR(P11/L11,0) -> 0
B12: abr | C12: 0 | D12: 0 | E12: 1244353.4 | F12: 1976134.1 | G12: 1534444.2 | H12: 1566103 | I12: 1693224 | J12: 2101324.4 | K12: 3595402.4 | L12: 3506507.7 | M12: =SUM(E12:K12) -> 13710986 | N12: 0 | O12: =IFERROR(N12/K12,0) -> 0 | P12: 0 | Q12: =IFERROR(P12/L12,0) -> 0
B13: mai | C13: 0 | D13: 0 | E13: 1351472.3 | F13: 1746599 | G13: 1659036.9 | H13: 2048940.4 | I13: 1885883.8 | J13: 2366944.9 | K13: 4151876.3 | L13: 3879670.2 | M13: =SUM(E13:K13) -> 15210754 | N13: 0 | O13: =IFERROR(N13/K13,0) -> 0 | P13: 0 | Q13: =IFERROR(P13/L13,0) -> 0
B14: jun | C14: 0 | D14: 0 | E14: 1318458.6 | F14: 1451346.8 | G14: 1552573.4 | H14: 1481714.1 | I14: 1764265.8 | J14: 2072026.8 | K14: 3351000 | L14: 3551913 | M14: =SUM(E14:K14) -> 12991386 | N14: 0 | O14: =IFERROR(N14/K14,0) -> 0 | P14: 0 | Q14: =IFERROR(P14/L14,0) -> 0
B15: jul | C15: 0 | D15: 0 | E15: 1323385.2 | F15: 1715013.5 | G15: 1745643 | H15: 1670738.2 | I15: 1838751.9 | J15: 2589934.3 | K15: 3282657.4 | L15: 3448372.3 | M15: =SUM(E15:K15) -> 14166123 | N15: 0 | O15: =IFERROR(N15/K15,0) -> 0 | P15: 0 | Q15: =IFERROR(P15/L15,0) -> 0
B16: ago | C16: 0 | D16: 0 | E16: 1361303.4 | F16: 1591077.9 | G16: 1682373.8 | H16: 1847051.9 | I16: 1775956.2 | J16: 2473569.1 | K16: 3439174.5 | L16: 0 | M16: =SUM(E16:K16) -> 14170507 | N16: 0 | O16: =IFERROR(N16/K16,0) -> 0 | P16: 0 | Q16: =IFERROR(P16/L16,0) -> 0
B17: set | C17: 0 | D17: 0 | E17: 1563896.2 | F17: 1635029.1 | G17: 1653421.6 | H17: 1338101.8 | I17: 1785955.8 | J17: 2583646.2 | K17: 3159965.1 | L17: 0 | M17: =SUM(E17:K17) -> 13720016 | N17: 350619.58 | O17: =IFERROR(N17/K17,0) -> 0.11095679 | P17: 0 | Q17: =IFERROR(P17/L17,0) -> 0
B18: out | C18: 0 | D18: 0 | E18: 1401246.3 | F18: 1544417.5 | G18: 1522057.5 | H18: 1423623.3 | I18: 1967214.5 | J18: 2548648.1 | K18: 3130191.1 | L18: 0 | M18: =SUM(E18:K18) -> 13537398 | N18: 443044.17 | O18: =IFERROR(N18/K18,0) -> 0.14153902 | P18: 0 | Q18: =IFERROR(P18/L18,0) -> 0
B19: nov | C19: 0 | D19: 0 | E19: 1298194.6 | F19: 1583709.4 | G19: 1535403.7 | H19: 1464639.9 | I19: 2044084.5 | J19: 2650839.5 | K19: 3225214.7 | L19: 0 | M19: =SUM(E19:K19) -> 13802086 | N19: 448236.66 | O19: =IFERROR(N19/K19,0) -> 0.13897886 | P19: 0 | Q19: =IFERROR(P19/L19,0) -> 0
B20: dez | C20: 0 | D20: 0 | E20: 1620219.4 | F20: 1484585.5 | G20: 1702434.3 | H20: 1625617.2 | I20: 1810363.8 | J20: 2532437.9 | K20: 2969722.9 | L20: 0 | M20: =SUM(E20:K20) -> 13745381 | N20: 584038.49 | O20: =IFERROR(N20/K20,0) -> 0.19666431 | P20: 0 | Q20: =IFERROR(P20/L20,0) -> 0
B21: Vencido | C21: Inad
B22: Mês | C22: 2012 | D22: 2013 | E22: 2014 | F22: 2015 | G22: 2016 | H22: 2017 | I22: 2018 | J22: 2019 | K22: 2020 | L22: <15/03/2012 | M22: 2021 | N22: Inadimp
B23: (vazio)
B24: jan | D24: 2777.77 | E24: 8061.74 | G24: 3525.88 | H24: 258.91 | I24: 3166.53 | J24: 34329.63 | K24: 3870.91 | M24: 31378.45 | N24: 87369.82
B25: fev | D25: 2777.77 | E25: 8061.74 | G25: 770.84 | H25: 607.11 | I25: 4527.46 | J25: 9072.94 | K25: 12548.46 | M25: 22258.35 | N25: 60624.67
B26: mar | C26: 4527.77 | D26: 8061.74 | E26: 8061.74 | G26: 2684.96 | I26: 5095.98 | J26: 3541.78 | K26: 36524.68 | M26: 30392.89 | N26: 98891.54
B27: abr | C27: 16854.7 | F27: 361.38 | G27: 1269.79 | H27: 1970.82 | I27: 1090.66 | J27: 833.92 | K27: 18327.49 | M27: 18878.02 | N27: 59586.78
B28: mai | C28: 16854.7 | D28: 8061.74 | G28: 1559.03 | H28: 14564.85 | I28: 2144.29 | J28: 19113.3 | K28: 3455.76 | M28: 204546.36 | N28: 270300.03
B29: jun | C29: 4704.7 | G29: 2522.61 | H29: 22751.24 | I29: 3521.48 | J29: 16890.46 | K29: 6663.36 | M29: 186750.43 | N29: 243804.28
B30: jul | C30: 4704.7 | D30: 8061.74 | G30: 984.96 | H30: 21219.99 | I30: 7615.54 | J30: 14355.2 | K30: 8411.25 | M30: 386808.28 | N30: 452161.66
B31: ago | C31: 4704.7 | F31: 6074.41 | G31: 3151.93 | H31: 22938.93 | I31: 9650.15 | J31: 4493.57 | K31: 5088.18 | N31: 56101.87
B32: set | C32: 8300.91 | D32: 8061.74 | G32: 4555.53 | H32: 4286.25 | J32: 11697.46 | K32: 8532.76 | N32: 45434.65
B33: out | C33: 4704.7 | D33: 8061.74 | E33: 351.16 | G33: 6106.35 | H33: 10006.18 | I33: 2259 | J33: 12126.86 | K33: 9023.07 | N33: 52639.06
B34: nov | C34: 2777.77 | D34: 8061.74 | G34: 8985.64 | H34: 10419.89 | I34: 8726.48 | J34: 8159.77 | K34: 8297.98 | N34: 55429.27
B35: dez | C35: 4544.66 | D35: 8061.74 | G35: 3391.2 | H35: 6426.53 | I35: 11959.83 | J35: 7283.9 | K35: 5904.7 | N35: 47572.56
B36: Inadimp | C36: 72679.31 | D36: 61987.72 | E36: 24536.38 | F36: 6435.79 | G36: 39508.72 | H36: 115450.7 | I36: 59757.4 | J36: 141898.79 | K36: 126648.6 | M36: 881012.78 | N36: 1529916.2

Sheet Régua
B2: Régua a Receber Vencido
B3: Data Análise | C3: 44407 | J3: =C3 -> 44407 | K3: 44389 | L3: 44383 | M3: 44308
B4: Dias Vencidos | C4: 10 dias | D4: 30 dias | E4: 60 dias | F4: 90 dias | G4: 120 dias | H4: 180 dias | I4: > 180 dias
B5: 0 | C5: 10 | D5: 30 | E5: 60 | F5: 90 | G5: 120 | H5: 180 | I5: >180 | J5: Inadimplência
B6: R$ Valor | C6: =SUMIFS(Dados!$H$2:$H$3422,Dados!$A$2:$A$3422,">="&($C3-C$5),Dados!$A$2:$A$3422,"<="&($C3-B5-1)) -> 166906.86 | D6: =SUMIFS(Dados!$H$2:$H$3422,Dados!$A$2:$A$3422,">="&($C3-D$5),Dados!$A$2:$A$3422,"<="&($C3-C5-1)) -> 193442.06 | E6: =SUMIFS(Dados!$H$2:$H$3422,Dados!$A$2:$A$3422,">="&($C3-E$5),Dados!$A$2:$A$3422,"<="&($C3-D5-1)) -> 192398.5 | F6: =SUMIFS(Dados!$H$2:$H$3422,Dados!$A$2:$A$3422,">="&($C3-F$5),Dados!$A$2:$A$3422,"<="&($C3-E5-1)) -> 190440.69 | G6: =SUMIFS(Dados!$H$2:$H$3422,Dados!$A$2:$A$3422,">="&($C3-G$5),Dados!$A$2:$A$3422,"<="&($C3-F5-1)) -> 18878.02 | H6: =SUMIFS(Dados!$H$2:$H$3422,Dados!$A$2:$A$3422,">="&($C3-H$5),Dados!$A$2:$A$3422,"<="&($C3-G5-1)) -> 52651.24 | I6: =SUMIFS(Dados!$H$2:$H$3422,Dados!$A$2:$A$3422,"<="&($C3-H5-1)) -> 680281.86 | J6: =SUM(C6:I6) -> 1494999.2 | K6: 1459289.4 | L6: 1507222.6 | M6: 1227948.6
B7: % Rep | C7: =C6/$J$6 -> 0.11164344 | D7: =D6/$J$6 -> 0.12939275 | E7: =E6/$J$6 -> 0.12869472 | F7: =F6/$J$6 -> 0.12738514 | G7: =G6/$J$6 -> 0.012627445 | H7: =H6/$J$6 -> 0.035218239 | I7: =I6/$J$6 -> 0.45503827 | J7: =J6/J6 -> 1
E8: CDC | F8: Judicial | G8: Judicial | H8: PCLD | J8: =H11 -> 0.036298522 | K8: 0.0352 | L8: 0.0371 | M8: 0.0267
B9: Fatura Consolidado | D9: =SUM(Indicador!L14) -> 3551913 | E9: =SUM(Indicador!L13:L14) -> 7431583.2 | F9: =SUM(Indicador!L12:L14) -> 10938091 | G9: =SUM(Indicador!L11:L14) -> 15828084 | H9: =SUM(Indicador!L9:L14) -> 22444919
B10: Receber Vencido | D10: =SUM(C6:D6) -> 360348.92 | E10: =SUM(C6:E6) -> 552747.42 | F10: =SUM(B6:F6) -> 743188.11 | G10: =SUM(C6:G6) -> 762066.13 | H10: =SUM(C6:H6) -> 814717.37
B11: Indicador Inadimplência | D11: =D10/D9 -> 0.10145207 | E11: =E10/E9 -> 0.074378151 | F11: =F10/F9 -> 0.067944956 | G11: =G10/G9 -> 0.048146454 | H11: =H10/H9 -> 0.036298522
B12: OBJETIVO
B13: 1,5% P/ 180 dias

Sheet Dash Ano
B4: Dados Vencidos até | D4: =Régua!C3 -> 44407
B5: Período | C5: R$ Vencido | D5: %Rep
B6: 2012 | C6: 72679.31 | D6: 0.047505419
B7: 2013 | C7: 61987.72 | D7: 0.040517069
B8: 2014 | C8: 24536.38 | D8: 0.016037728
B9: 2015 | C9: 6435.79 | D9: 0.0042066291
B10: 2016 | C10: 39508.72 | D10: 0.025824107
B11: 2017 | C11: 115450.7 | D11: 0.075462108
B12: 2018 | C12: 59757.4 | D12: 0.039059264
B13: 2019 | C13: 141898.79 | D13: 0.092749388
B14: 2020 | C14: 126648.6 | D14: 0.082781397
B15: <15/03/2012 | D15: 0
B16: 2021 | C16: 881012.78 | D16: 0.57585689
B17: Total Geral | C17: 1529916.2 | D17: 1

Sheet Dash Vendedor
B4: Dados Vencidos até | C4: =Régua!C3 -> 44407
B5: Período | C5: R$ Vencido | D5: %Rep
B6: ALEXANDRE FARIAS GOMES | C6: 51689.48 | D6: 0.033785825
B7: ANGELA MARIA FARIAS LIMA | C7: 30323.51 | D7: 0.019820373
B8: ANTONIA VALDENES MOREIRA | C8: 119270.23 | D8: 0.077958669
B9: ANTONIO SILVANOR DOS SANTOS | C9: 11078.6 | D9: 0.0072413117
B10: ARNALDO RAMOS DE AGUIAR | C10: 6904.93 | D10: 0.0045132734
B11: CLEONARDO CAMPOS TEIXEIRA | C11: 414.88 | D11: 0.00027117825
B12: EDILBERTO XAVIER DOS SANTOS | C12: 11651.97 | D12: 0.0076160839
B13: ESIO GOMES NOGUEIRA | C13: 434.9 | D13: 0.00028426394
B14: FRANCISCO JOSE DA SILVA FERREIRA | C14: 10022.23 | D14: 0.006550836
B15: INGRID LORRANY DO NASCIMENTO GADELHA | C15: 100897.6 | D15: 0.065949756
B16: JARDEL MONTEIRO | C16: 1138.74 | D16: 0.00074431528
B17: JOÃO BATISTA FERNANDES PIMENTEL | C17: 153489.15 | D17: 0.1003252
... B34: Total Geral | C34: 1529916.2 | D34: 1

Sheet Dash Cliente
B4: ='Dash Ano'!B4 -> Dados Vencidos até | C4: ='Dash Ano'!D4 -> 44407
B5: Cliente | C5: R$ Vencido | D5: %Rep
B6: FARMACIA DO TRAB DE HORIZONTE LTDA | C6: 156634.2 | D6: 0.1023809 | F6: =SUM(D6:D27) -> 0.67694506
B7: FRANCISCA LOPES CARNEIRO ME | C7: 153489.15 | D7: 0.1003252
B8: FCIA DO TRAB CENTRAL LTDA ME | C8: 149479.51 | D8: 0.097704378
B9: FCIA DO TRAB CENTRAL DE PACAJUS LTDA-ME | C9: 99172.78 | D9: 0.064822361
B10: PLACIDO COMERCIAL DE MEDIC LTDA -ME | C10: 56409.81 | D10: 0.036871177
B11: FARMACIA IPARANA LTDA ME - FL | C11: 36026.05 | D11: 0.023547728
B12: IGOR PINTO ALVES - MZ | C12: 35751.34 | D12: 0.023368169
B13: FARMACIA TELE JUCA LTDA FILIAL-2 | C13: 35680.22 | D13: 0.023321683
B14: FARMACIA DO TRAB REDENCIONISTA LTDA - ME | C14: 35292.89 | D14: 0.023068512
B15: DROGARIA NOGUEIRA & BARBOSA-ME | C15: 34401.81 | D15: 0.022486075
B16: FARMACIA VARJOTENSE - EIRELI | C16: 28778.59 | D16: 0.018810566
B17: M L MARQUES COM DE PROD FARM ME | C17: 25917.58 | D17: 0.016940523
B18: IPHARMA EMPREEND FARMAC LTDA EPP | C18: 24604.78 | D18: 0.016082437
... B246: FCIA DA ECONOMIA NACIONAL-MZ | C246: 115.12 | D246: 7.5245952e-05
B247: (vazio) | D247: 0
B248: Total Geral | C248: 1529916.2 | D248: 1
